2025-08-17 14:32:05,234 [INFO] Step-1: Folder created: uploads/34a6e2a0-2b76-44fb-b63f-71e23c0619e7
2025-08-17 14:32:05,237 [INFO] Using Python executable: venv1/bin/python3
2025-08-17 14:32:05,237 [INFO] Step-2: File sent {'questions.txt': 'uploads/34a6e2a0-2b76-44fb-b63f-71e23c0619e7/question.txt', 'data.csv': 'uploads/34a6e2a0-2b76-44fb-b63f-71e23c0619e7/sales.csv'}
2025-08-17 14:32:05,237 [INFO] ü§ñ Step-1: Getting scrap code and metadata from llm. Tries count = 0
2025-08-17 14:32:19,109 [INFO] ü§ñ Step-1: Successfully parsed response from LLM.
2025-08-17 14:32:19,110 [INFO] üíª Step-3: Entering loop
2025-08-17 14:32:19,110 [INFO] üíª Loop-1: Running LLM code.
2025-08-17 14:32:19,111 [ERROR] ‚ùåüíª Loop-1: Code execution failed: ‚ùå Failed to install library 'requests': [Errno 2] No such file or directory: 'venv1/bin/python3'
2025-08-17 14:32:19,111 [INFO] ü§ñ Loop-1: Inside Loop LLM call.
2025-08-17 14:32:28,434 [INFO] üíª Loop-2: Running LLM code.
2025-08-17 14:32:28,435 [ERROR] ‚ùåüíª Loop-2: Code execution failed: ‚ùå Failed to install library 'pandas': [Errno 2] No such file or directory: 'venv1/bin/python3'
2025-08-17 14:32:28,435 [INFO] ü§ñ Loop-2: Inside Loop LLM call.
2025-08-17 14:32:42,089 [INFO] üíª Loop-3: Running LLM code.
2025-08-17 14:32:42,099 [ERROR] ‚ùåüíª Loop-3: Code execution failed: ‚ùå Error during code execution: Traceback (most recent call last): File "/home/azureuser/TDS_project2/task_engine.py", line 67, in run_python_code result = subprocess.run( ^^^^^^^^^^^^^^^ File "/home/azureuser/.local/share/uv/python/cpython-3.11.13-linux-x86_64-gnu/lib/python3.11/subprocess.py", line 548, in run with Popen(*popenargs, **kwargs) as process: ^^^^^^^^^^^^^^^^^^^^^^^^^^^ File "/home/azureuser/.local/share/uv/python/cpython-3.11.13-linux-x86_64-gnu/lib/python3.11/subprocess.py", line 1026, in __init__ self._execute_child(args, executable, preexec_fn, close_fds, File "/home/azureuser/.local/share/uv/python/cpython-3.11.13-linux-x86_64-gnu/lib/python3.11/subprocess.py", line 1955, in _execute_child raise child_exception_type(errno_num, err_msg, err_filename) FileNotFoundError: [Errno 2] No such file or directory: 'venv1/bin/python3'
2025-08-17 14:32:42,100 [INFO] ü§ñ Loop-3: Inside Loop LLM call.
2025-08-17 14:33:26,808 [INFO] üíª Loop-4: Running LLM code.
2025-08-17 14:33:26,809 [ERROR] ‚ùåüíª Loop-4: Code execution failed: ‚ùå Failed to install library 'pandas': [Errno 2] No such file or directory: 'venv1/bin/python3'
2025-08-17 14:33:26,809 [INFO] ü§ñ Loop-4: Inside Loop LLM call.
2025-08-17 14:34:32,205 [INFO] üíª Loop-5: Running LLM code.
2025-08-17 14:34:32,243 [ERROR] ‚ùåüíª Loop-5: Code execution failed: ‚ùå Error during code execution: Traceback (most recent call last): File "/home/azureuser/TDS_project2/task_engine.py", line 67, in run_python_code result = subprocess.run( ^^^^^^^^^^^^^^^ File "/home/azureuser/.local/share/uv/python/cpython-3.11.13-linux-x86_64-gnu/lib/python3.11/subprocess.py", line 548, in run with Popen(*popenargs, **kwargs) as process: ^^^^^^^^^^^^^^^^^^^^^^^^^^^ File "/home/azureuser/.local/share/uv/python/cpython-3.11.13-linux-x86_64-gnu/lib/python3.11/subprocess.py", line 1026, in __init__ self._execute_child(args, executable, preexec_fn, close_fds, File "/home/azureuser/.local/share/uv/python/cpython-3.11.13-linux-x86_64-gnu/lib/python3.11/subprocess.py", line 1955, in _execute_child raise child_exception_type(errno_num, err_msg, err_filename) FileNotFoundError: [Errno 2] No such file or directory: 'venv1/bin/python3'
2025-08-17 14:34:32,244 [INFO] ü§ñ Loop-5: Inside Loop LLM call.
2025-08-17 14:35:39,551 [INFO] üíª Loop-6: Running LLM code.
2025-08-17 14:35:39,604 [ERROR] ‚ùåüíª Loop-6: Code execution failed: ‚ùå Error during code execution: Traceback (most recent call last): File "/home/azureuser/TDS_project2/task_engine.py", line 67, in run_python_code result = subprocess.run( ^^^^^^^^^^^^^^^ File "/home/azureuser/.local/share/uv/python/cpython-3.11.13-linux-x86_64-gnu/lib/python3.11/subprocess.py", line 548, in run with Popen(*popenargs, **kwargs) as process: ^^^^^^^^^^^^^^^^^^^^^^^^^^^ File "/home/azureuser/.local/share/uv/python/cpython-3.11.13-linux-x86_64-gnu/lib/python3.11/subprocess.py", line 1026, in __init__ self._execute_child(args, executable, preexec_fn, close_fds, File "/home/azureuser/.local/share/uv/python/cpython-3.11.13-linux-x86_64-gnu/lib/python3.11/subprocess.py", line 1955, in _execute_child raise child_exception_type(errno_num, err_msg, err_filename) FileNotFoundError: [Errno 2] No such file or directory: 'venv1/bin/python3'
2025-08-17 14:35:39,605 [INFO] ü§ñ Loop-6: Inside Loop LLM call.
2025-08-17 14:36:08,236 [INFO] üíª Loop-7: Running LLM code.
2025-08-17 14:36:08,289 [ERROR] ‚ùåüíª Loop-7: Code execution failed: ‚ùå Error during code execution: Traceback (most recent call last): File "/home/azureuser/TDS_project2/task_engine.py", line 67, in run_python_code result = subprocess.run( ^^^^^^^^^^^^^^^ File "/home/azureuser/.local/share/uv/python/cpython-3.11.13-linux-x86_64-gnu/lib/python3.11/subprocess.py", line 548, in run with Popen(*popenargs, **kwargs) as process: ^^^^^^^^^^^^^^^^^^^^^^^^^^^ File "/home/azureuser/.local/share/uv/python/cpython-3.11.13-linux-x86_64-gnu/lib/python3.11/subprocess.py", line 1026, in __init__ self._execute_child(args, executable, preexec_fn, close_fds, File "/home/azureuser/.local/share/uv/python/cpython-3.11.13-linux-x86_64-gnu/lib/python3.11/subprocess.py", line 1955, in _execute_child raise child_exception_type(errno_num, err_msg, err_filename) FileNotFoundError: [Errno 2] No such file or directory: 'venv1/bin/python3'
2025-08-17 14:36:08,290 [INFO] ü§ñ Loop-7: Inside Loop LLM call.
2025-08-17 14:36:59,802 [INFO] üíª Loop-8: Running LLM code.
2025-08-17 14:36:59,932 [ERROR] ‚ùåüíª Loop-8: Code execution failed: ‚ùå Error during code execution: Traceback (most recent call last): File "/home/azureuser/TDS_project2/task_engine.py", line 67, in run_python_code result = subprocess.run( ^^^^^^^^^^^^^^^ File "/home/azureuser/.local/share/uv/python/cpython-3.11.13-linux-x86_64-gnu/lib/python3.11/subprocess.py", line 548, in run with Popen(*popenargs, **kwargs) as process: ^^^^^^^^^^^^^^^^^^^^^^^^^^^ File "/home/azureuser/.local/share/uv/python/cpython-3.11.13-linux-x86_64-gnu/lib/python3.11/subprocess.py", line 1026, in __init__ self._execute_child(args, executable, preexec_fn, close_fds, File "/home/azureuser/.local/share/uv/python/cpython-3.11.13-linux-x86_64-gnu/lib/python3.11/subprocess.py", line 1955, in _execute_child raise child_exception_type(errno_num, err_msg, err_filename) FileNotFoundError: [Errno 2] No such file or directory: 'venv1/bin/python3'
2025-08-17 14:36:59,932 [INFO] ü§ñ Loop-8: Inside Loop LLM call.
2025-08-17 14:37:30,059 [INFO] üíª Loop-9: Running LLM code.
2025-08-17 14:37:30,118 [ERROR] ‚ùåüíª Loop-9: Code execution failed: ‚ùå Error during code execution: Traceback (most recent call last): File "/home/azureuser/TDS_project2/task_engine.py", line 67, in run_python_code result = subprocess.run( ^^^^^^^^^^^^^^^ File "/home/azureuser/.local/share/uv/python/cpython-3.11.13-linux-x86_64-gnu/lib/python3.11/subprocess.py", line 548, in run with Popen(*popenargs, **kwargs) as process: ^^^^^^^^^^^^^^^^^^^^^^^^^^^ File "/home/azureuser/.local/share/uv/python/cpython-3.11.13-linux-x86_64-gnu/lib/python3.11/subprocess.py", line 1026, in __init__ self._execute_child(args, executable, preexec_fn, close_fds, File "/home/azureuser/.local/share/uv/python/cpython-3.11.13-linux-x86_64-gnu/lib/python3.11/subprocess.py", line 1955, in _execute_child raise child_exception_type(errno_num, err_msg, err_filename) FileNotFoundError: [Errno 2] No such file or directory: 'venv1/bin/python3'
2025-08-17 14:37:30,118 [INFO] ü§ñ Loop-9: Inside Loop LLM call.
2025-08-17 14:38:19,997 [INFO] üíª Loop-10: Running LLM code.
2025-08-17 14:38:20,059 [ERROR] ‚ùåüíª Loop-10: Code execution failed: ‚ùå Error during code execution: Traceback (most recent call last): File "/home/azureuser/TDS_project2/task_engine.py", line 67, in run_python_code result = subprocess.run( ^^^^^^^^^^^^^^^ File "/home/azureuser/.local/share/uv/python/cpython-3.11.13-linux-x86_64-gnu/lib/python3.11/subprocess.py", line 548, in run with Popen(*popenargs, **kwargs) as process: ^^^^^^^^^^^^^^^^^^^^^^^^^^^ File "/home/azureuser/.local/share/uv/python/cpython-3.11.13-linux-x86_64-gnu/lib/python3.11/subprocess.py", line 1026, in __init__ self._execute_child(args, executable, preexec_fn, close_fds, File "/home/azureuser/.local/share/uv/python/cpython-3.11.13-linux-x86_64-gnu/lib/python3.11/subprocess.py", line 1955, in _execute_child raise child_exception_type(errno_num, err_msg, err_filename) FileNotFoundError: [Errno 2] No such file or directory: 'venv1/bin/python3'
2025-08-17 14:38:20,059 [INFO] ü§ñ Loop-10: Inside Loop LLM call.
2025-08-17 14:38:46,892 [INFO] üíª Loop-11: Running LLM code.
2025-08-17 14:38:46,950 [ERROR] ‚ùåüíª Loop-11: Code execution failed: ‚ùå Error during code execution: Traceback (most recent call last): File "/home/azureuser/TDS_project2/task_engine.py", line 67, in run_python_code result = subprocess.run( ^^^^^^^^^^^^^^^ File "/home/azureuser/.local/share/uv/python/cpython-3.11.13-linux-x86_64-gnu/lib/python3.11/subprocess.py", line 548, in run with Popen(*popenargs, **kwargs) as process: ^^^^^^^^^^^^^^^^^^^^^^^^^^^ File "/home/azureuser/.local/share/uv/python/cpython-3.11.13-linux-x86_64-gnu/lib/python3.11/subprocess.py", line 1026, in __init__ self._execute_child(args, executable, preexec_fn, close_fds, File "/home/azureuser/.local/share/uv/python/cpython-3.11.13-linux-x86_64-gnu/lib/python3.11/subprocess.py", line 1955, in _execute_child raise child_exception_type(errno_num, err_msg, err_filename) FileNotFoundError: [Errno 2] No such file or directory: 'venv1/bin/python3'
2025-08-17 14:38:46,951 [INFO] ü§ñ Loop-11: Inside Loop LLM call.
2025-08-17 14:39:37,744 [INFO] üíª Loop-12: Running LLM code.
2025-08-17 14:39:37,800 [ERROR] ‚ùåüíª Loop-12: Code execution failed: ‚ùå Error during code execution: Traceback (most recent call last): File "/home/azureuser/TDS_project2/task_engine.py", line 67, in run_python_code result = subprocess.run( ^^^^^^^^^^^^^^^ File "/home/azureuser/.local/share/uv/python/cpython-3.11.13-linux-x86_64-gnu/lib/python3.11/subprocess.py", line 548, in run with Popen(*popenargs, **kwargs) as process: ^^^^^^^^^^^^^^^^^^^^^^^^^^^ File "/home/azureuser/.local/share/uv/python/cpython-3.11.13-linux-x86_64-gnu/lib/python3.11/subprocess.py", line 1026, in __init__ self._execute_child(args, executable, preexec_fn, close_fds, File "/home/azureuser/.local/share/uv/python/cpython-3.11.13-linux-x86_64-gnu/lib/python3.11/subprocess.py", line 1955, in _execute_child raise child_exception_type(errno_num, err_msg, err_filename) FileNotFoundError: [Errno 2] No such file or directory: 'venv1/bin/python3'
2025-08-17 14:39:37,801 [INFO] ü§ñ Loop-12: Inside Loop LLM call.
2025-08-17 14:40:13,825 [INFO] üíª Loop-13: Running LLM code.
2025-08-17 14:40:13,880 [ERROR] ‚ùåüíª Loop-13: Code execution failed: ‚ùå Error during code execution: Traceback (most recent call last): File "/home/azureuser/TDS_project2/task_engine.py", line 67, in run_python_code result = subprocess.run( ^^^^^^^^^^^^^^^ File "/home/azureuser/.local/share/uv/python/cpython-3.11.13-linux-x86_64-gnu/lib/python3.11/subprocess.py", line 548, in run with Popen(*popenargs, **kwargs) as process: ^^^^^^^^^^^^^^^^^^^^^^^^^^^ File "/home/azureuser/.local/share/uv/python/cpython-3.11.13-linux-x86_64-gnu/lib/python3.11/subprocess.py", line 1026, in __init__ self._execute_child(args, executable, preexec_fn, close_fds, File "/home/azureuser/.local/share/uv/python/cpython-3.11.13-linux-x86_64-gnu/lib/python3.11/subprocess.py", line 1955, in _execute_child raise child_exception_type(errno_num, err_msg, err_filename) FileNotFoundError: [Errno 2] No such file or directory: 'venv1/bin/python3'
2025-08-17 14:40:13,880 [INFO] ü§ñ Loop-13: Inside Loop LLM call.
2025-08-17 14:40:43,251 [INFO] üíª Step-6: Running final code.
2025-08-17 14:40:43,394 [ERROR] ‚ùåüíª Step-6: Final code execution failed: ‚ùå Error during code execution: Traceback (most recent call last): File "/home/azureuser/TDS_project2/task_engine.py", line 67, in run_python_code result = subprocess.run( ^^^^^^^^^^^^^^^ File "/home/azureuser/.local/share/uv/python/cpython-3.11.13-linux-x86_64-gnu/lib/python3.11/subprocess.py", line 548, in run with Popen(*popenargs, **kwargs) as process: ^^^^^^^^^^^^^^^^^^^^^^^^^^^ File "/home/azureuser/.local/share/uv/python/cpython-3.11.13-linux-x86_64-gnu/lib/python3.11/subprocess.py", line 1026, in __init__ self._execute_child(args, executable, preexec_fn, close_fds, File "/home/azureuser/.local/share/uv/python/cpython-3.11.13-linux-x86_64-gnu/lib/python3.11/subprocess.py", line 1955, in _execute_child raise child_exception_type(errno_num, err_msg, err_filename) FileNotFoundError: [Errno 2] No such file or directory: 'venv1/bin/python3'
2025-08-17 14:40:43,394 [ERROR] ‚ùåüìÅ Step-7: result.json not found. Checking for result.txt.
2025-08-17 14:40:43,395 [ERROR] ‚ùåüìÅ result.txt not found.
